2023-03-24 14:59:43,033 - logger_celery - ERROR - add text campaign: yandex direct error - (api.py:438)
2023-03-24 16:45:25,735 - logger_celery - ERROR - data to db: (psycopg2.errors.UndefinedColumn) column "task_id" of relation "ya_ads_addgroups" does not exist
LINE 1: ...feed_category_ids, text_feed_id, tracking_params, task_id, r...
                                                             ^

[SQL: INSERT INTO ya_ads_addgroups (campaign_id, dynamic_text_autotargeting_accessory, dynamic_text_autotargeting_alternative, dynamic_text_autotargeting_broader, dynamic_text_autotargeting_competitor, dynamic_text_autotargeting_exact, dynamic_text_domain_urls, dynamic_text_feed_autotargeting_accessory, dynamic_text_feed_autotargeting_alternative, dynamic_text_feed_autotargeting_broader, dynamic_text_feed_autotargeting_competitor, dynamic_text_feed_autotargeting_exact, dynamic_text_feed_ids, login, name, negative_keyword_set_ids, negative_keywords, region_ids, text_feed_category_ids, text_feed_id, tracking_params, task_id, res_errors, date_time) VALUES (%(campaign_id)s, %(dynamic_text_autotargeting_accessory)s, %(dynamic_text_autotargeting_alternative)s, %(dynamic_text_autotargeting_broader)s, %(dynamic_text_autotargeting_competitor)s, %(dynamic_text_autotargeting_exact)s, %(dynamic_text_domain_urls)s, %(dynamic_text_feed_autotargeting_accessory)s, %(dynamic_text_feed_autotargeting_alternative)s, %(dynamic_text_feed_autotargeting_broader)s, %(dynamic_text_feed_autotargeting_competitor)s, %(dynamic_text_feed_autotargeting_exact)s, %(dynamic_text_feed_ids)s, %(login)s, %(name)s, %(negative_keyword_set_ids)s, %(negative_keywords)s, %(region_ids)s, %(text_feed_category_ids)s, %(text_feed_id)s, %(tracking_params)s, %(task_id)s, %(res_errors)s, %(date_time)s)]
[parameters: {'campaign_id': 123456, 'dynamic_text_autotargeting_accessory': 'YES', 'dynamic_text_autotargeting_alternative': 'YES', 'dynamic_text_autotargeting_broader': 'YES', 'dynamic_text_autotargeting_competitor': 'YES', 'dynamic_text_autotargeting_exact': 'YES', 'dynamic_text_domain_urls': 'www.site.com', 'dynamic_text_feed_autotargeting_accessory': 'YES', 'dynamic_text_feed_autotargeting_alternative': 'YES', 'dynamic_text_feed_autotargeting_broader': 'YES', 'dynamic_text_feed_autotargeting_competitor': 'YES', 'dynamic_text_feed_autotargeting_exact': 'YES', 'dynamic_text_feed_ids': 12321, 'login': 'ecomru-408641-xm1b@yandex.ru', 'name': 'abcdef', 'negative_keyword_set_ids': [123, 456, 789], 'negative_keywords': ['диван', 'кровать'], 'region_ids': [11, 12, 13, -14], 'text_feed_category_ids': [123, 456, 789], 'text_feed_id': 123456, 'tracking_params': 'from=direct&ad={ad_id}', 'task_id': '1e555bf4-1a84-425e-8e85-382bf7bca5cd', 'res_errors': ['{"Code": 5009, "Message": "More than one field was sent", "Details": "Only one of the  fields must be specified"}'], 'date_time': datetime.datetime(2023, 3, 24, 16, 45, 25, 175176)}]
(Background on this error at: https://sqlalche.me/e/14/f405) - (db_work.py:59)
2023-03-24 16:45:30,781 - logger_celery - ERROR - data to db: (psycopg2.errors.InFailedSqlTransaction) current transaction is aborted, commands ignored until end of transaction block

[SQL: select relname from pg_class c join pg_namespace n on n.oid=c.relnamespace where pg_catalog.pg_table_is_visible(c.oid) and relname=%(name)s]
[parameters: {'name': 'ya_ads_addgroups'}]
(Background on this error at: https://sqlalche.me/e/14/2j85) - (db_work.py:59)
2023-03-24 16:45:35,788 - logger_celery - ERROR - data to db error - (db_work.py:62)
2023-03-24 16:48:36,711 - logger_celery - ERROR - add group async: (psycopg2.OperationalError) server closed the connection unexpectedly
	This probably means the server terminated abnormally
	before or while processing the request.
server closed the connection unexpectedly
	This probably means the server terminated abnormally
	before or while processing the request.

(Background on this error at: https://sqlalche.me/e/14/e3q8) - (api.py:894)
2023-03-24 16:48:36,711 - logger_celery - ERROR - add group async: (psycopg2.OperationalError) server closed the connection unexpectedly
	This probably means the server terminated abnormally
	before or while processing the request.
server closed the connection unexpectedly
	This probably means the server terminated abnormally
	before or while processing the request.

(Background on this error at: https://sqlalche.me/e/14/e3q8) - (api.py:894)
2023-03-24 18:24:25,327 - logger_celery - ERROR - data to db: (psycopg2.errors.UndefinedColumn) column "task_id" of relation "ya_ads_addads" does not exist
LINE 1: ...xt_price_currency, txt_price_qualifier, vcard_id, task_id, r...
                                                             ^

[SQL: INSERT INTO ya_ads_addads (ad_extension_ids, ad_image_hash, ads_group_id, business_id, creative_id, display_url_path, ext_link_params, href, login, mobile, prefer_vcard_over_business, sitelink_set_id, text, title, title2, turbo_page_id, txt_old_price, txt_price, txt_price_currency, txt_price_qualifier, vcard_id, task_id, res_errors, date_time) VALUES (%(ad_extension_ids)s, %(ad_image_hash)s, %(ads_group_id)s, %(business_id)s, %(creative_id)s, %(display_url_path)s, %(ext_link_params)s, %(href)s, %(login)s, %(mobile)s, %(prefer_vcard_over_business)s, %(sitelink_set_id)s, %(text)s, %(title)s, %(title2)s, %(turbo_page_id)s, %(txt_old_price)s, %(txt_price)s, %(txt_price_currency)s, %(txt_price_qualifier)s, %(vcard_id)s, %(task_id)s, %(res_errors)s, %(date_time)s)]
[parameters: {'ad_extension_ids': [12345, 7890], 'ad_image_hash': 'wodjwb979fcu131ewhfiw134', 'ads_group_id': 123456, 'business_id': 123456, 'creative_id': 123456, 'display_url_path': 'NO', 'ext_link_params': 'false', 'href': 'https://site.ru', 'login': 'ecomru-408641-xm1b@yandex.ru', 'mobile': 'NO', 'prefer_vcard_over_business': 'NO', 'sitelink_set_id': 123456, 'text': 'some text какой-то текст', 'title': 'абвгabcd', 'title2': 'абвгabcd', 'turbo_page_id': 123456, 'txt_old_price': 10000, 'txt_price': 9999, 'txt_price_currency': 'USD', 'txt_price_qualifier': 'FROM', 'vcard_id': 123456, 'task_id': 'e7617d40-494f-4c74-8923-e892130fc11a', 'res_errors': ['{"Code": 8800, "Message": "Object not found", "Details": "Company not found"}', '{"Code": 8800, "Message": "Object not found", "Details": "Набор быс ... (486 characters truncated) ... d", "Details": "Extension 12345 not found"}', '{"Code": 5005, "Message": "Field set incorrectly", "Details": "Старая цена должна быть больше новой"}'], 'date_time': datetime.datetime(2023, 3, 24, 18, 24, 24, 845580)}]
(Background on this error at: https://sqlalche.me/e/14/f405) - (db_work.py:59)
2023-03-24 18:24:30,377 - logger_celery - ERROR - data to db: (psycopg2.errors.InFailedSqlTransaction) current transaction is aborted, commands ignored until end of transaction block

[SQL: select relname from pg_class c join pg_namespace n on n.oid=c.relnamespace where pg_catalog.pg_table_is_visible(c.oid) and relname=%(name)s]
[parameters: {'name': 'ya_ads_addads'}]
(Background on this error at: https://sqlalche.me/e/14/2j85) - (db_work.py:59)
2023-03-24 18:24:35,402 - logger_celery - ERROR - data to db error - (db_work.py:62)
2023-03-24 18:26:57,522 - logger_celery - ERROR - add ad async: (psycopg2.OperationalError) server closed the connection unexpectedly
	This probably means the server terminated abnormally
	before or while processing the request.
server closed the connection unexpectedly
	This probably means the server terminated abnormally
	before or while processing the request.

(Background on this error at: https://sqlalche.me/e/14/e3q8) - (api.py:1177)
2023-03-24 18:26:57,522 - logger_celery - ERROR - add ad async: (psycopg2.OperationalError) server closed the connection unexpectedly
	This probably means the server terminated abnormally
	before or while processing the request.
server closed the connection unexpectedly
	This probably means the server terminated abnormally
	before or while processing the request.

(Background on this error at: https://sqlalche.me/e/14/e3q8) - (api.py:1177)
2023-03-24 18:29:30,887 - logger_celery - ERROR - data to db: (psycopg2.errors.UndefinedColumn) column "task_id" of relation "ya_ads_addads" does not exist
LINE 1: ...xt_price_currency, txt_price_qualifier, vcard_id, task_id, r...
                                                             ^

[SQL: INSERT INTO ya_ads_addads (ad_extension_ids, ad_image_hash, ads_group_id, business_id, creative_id, display_url_path, ext_link_params, href, login, mobile, prefer_vcard_over_business, sitelink_set_id, text, title, title2, turbo_page_id, txt_old_price, txt_price, txt_price_currency, txt_price_qualifier, vcard_id, task_id, res_errors, date_time) VALUES (%(ad_extension_ids)s, %(ad_image_hash)s, %(ads_group_id)s, %(business_id)s, %(creative_id)s, %(display_url_path)s, %(ext_link_params)s, %(href)s, %(login)s, %(mobile)s, %(prefer_vcard_over_business)s, %(sitelink_set_id)s, %(text)s, %(title)s, %(title2)s, %(turbo_page_id)s, %(txt_old_price)s, %(txt_price)s, %(txt_price_currency)s, %(txt_price_qualifier)s, %(vcard_id)s, %(task_id)s, %(res_errors)s, %(date_time)s)]
[parameters: {'ad_extension_ids': [12345, 7890], 'ad_image_hash': 'wodjwb979fcu131ewhfiw134', 'ads_group_id': 123456, 'business_id': 123456, 'creative_id': 123456, 'display_url_path': 'NO', 'ext_link_params': 'false', 'href': 'https://site.ru', 'login': 'ecomru-408641-xm1b@yandex.ru', 'mobile': 'NO', 'prefer_vcard_over_business': 'NO', 'sitelink_set_id': 123456, 'text': 'some text какой-то текст', 'title': 'абвгabcd', 'title2': 'абвгabcd', 'turbo_page_id': 123456, 'txt_old_price': 10000, 'txt_price': 9999, 'txt_price_currency': 'USD', 'txt_price_qualifier': 'FROM', 'vcard_id': 123456, 'task_id': '755689f7-52c7-494c-8dec-ba53cc86a784', 'res_errors': ['{"Code": 8800, "Message": "Object not found", "Details": "Company not found"}', '{"Code": 8800, "Message": "Object not found", "Details": "Набор быс ... (486 characters truncated) ... d", "Details": "Extension 12345 not found"}', '{"Code": 5005, "Message": "Field set incorrectly", "Details": "Старая цена должна быть больше новой"}'], 'date_time': datetime.datetime(2023, 3, 24, 18, 29, 30, 613169)}]
(Background on this error at: https://sqlalche.me/e/14/f405) - (db_work.py:59)
2023-03-24 18:29:35,905 - logger_celery - ERROR - data to db: (psycopg2.errors.InFailedSqlTransaction) current transaction is aborted, commands ignored until end of transaction block

[SQL: select relname from pg_class c join pg_namespace n on n.oid=c.relnamespace where pg_catalog.pg_table_is_visible(c.oid) and relname=%(name)s]
[parameters: {'name': 'ya_ads_addads'}]
(Background on this error at: https://sqlalche.me/e/14/2j85) - (db_work.py:59)
2023-03-24 18:29:40,922 - logger_celery - ERROR - data to db error - (db_work.py:62)
2023-03-24 18:31:35,342 - logger_celery - ERROR - add ad async: (psycopg2.OperationalError) server closed the connection unexpectedly
	This probably means the server terminated abnormally
	before or while processing the request.
server closed the connection unexpectedly
	This probably means the server terminated abnormally
	before or while processing the request.

(Background on this error at: https://sqlalche.me/e/14/e3q8) - (api.py:1177)
2023-03-24 18:31:35,342 - logger_celery - ERROR - add ad async: (psycopg2.OperationalError) server closed the connection unexpectedly
	This probably means the server terminated abnormally
	before or while processing the request.
server closed the connection unexpectedly
	This probably means the server terminated abnormally
	before or while processing the request.

(Background on this error at: https://sqlalche.me/e/14/e3q8) - (api.py:1177)
2023-03-24 18:38:16,107 - logger_celery - ERROR - add ad async: (psycopg2.OperationalError) server closed the connection unexpectedly
	This probably means the server terminated abnormally
	before or while processing the request.
server closed the connection unexpectedly
	This probably means the server terminated abnormally
	before or while processing the request.

(Background on this error at: https://sqlalche.me/e/14/e3q8) - (api.py:1177)
2023-03-24 18:39:12,529 - logger_celery - ERROR - add ad async: (psycopg2.OperationalError) server closed the connection unexpectedly
	This probably means the server terminated abnormally
	before or while processing the request.
server closed the connection unexpectedly
	This probably means the server terminated abnormally
	before or while processing the request.

(Background on this error at: https://sqlalche.me/e/14/e3q8) - (api.py:1177)
2023-03-24 18:53:09,537 - logger_celery - ERROR - add ad async: (psycopg2.OperationalError) server closed the connection unexpectedly
	This probably means the server terminated abnormally
	before or while processing the request.
server closed the connection unexpectedly
	This probably means the server terminated abnormally
	before or while processing the request.

(Background on this error at: https://sqlalche.me/e/14/e3q8) - (api.py:1186)
2023-03-24 18:53:09,537 - logger_celery - ERROR - add ad async: (psycopg2.OperationalError) server closed the connection unexpectedly
	This probably means the server terminated abnormally
	before or while processing the request.
server closed the connection unexpectedly
	This probably means the server terminated abnormally
	before or while processing the request.

(Background on this error at: https://sqlalche.me/e/14/e3q8) - (api.py:1186)
